Workbook

Sheet Historical Data
A1: 2023 | E1: =-1*SLOPE($E$4:$E$13,A4:A13) -> 9.2242424 | F1: =(-12*E1+INTERCEPT(E4:E13,A4:A13))/13 -> 8.9282051 | P1: AVERAGE | T1: (24 & 23 only due to rule changes)
B2: R | C2: HR | D2: RBI | E2: SB | F2: OBP | G2: SLG | H2: K | I2: QS | J2: ERA | K2: WHIP | L2: K/BB | M2: SVHD | Q2: R | R2: HR | S2: RBI | T2: SB | U2: OBP | V2: SLG | W2: K | X2: QS | Y2: ERA | Z2: WHIP | AA2: K/BB | AB2: SVHD
A3: 1 | B3: 1126 | C3: 330 | D3: 1098 | E3: 213 | F3: 0.341 | G3: 0.4658 | H3: 1809 | I3: 131 | J3: 3.537 | K3: 1.142 | L3: 3.634 | M3: 192 | P3: 1 | Q3: =(4*B95+3*B66+2*B3+B19+B35)/11 -> 1074.9091 | R3: =(4*C95+3*C66+2*C3+C19+C35)/11 -> 335.09091 | S3: =(4*D95+3*D66+2*D3+D19+D35)/11 -> 1081.5455 | T3: =(4*E95+3*E66+2*E3+E19+E35)/11 -> 216.18182 | U3: =(4*F95+3*F66+2*F3+F19+F35)/11 -> 0.3418 | V3: =(4*G95+3*G66+2*G3+G19+G35)/11 -> 0.46048182 | W3: =(4*H95+3*H66+2*H3+H19+H35)/11 -> 1800.4545 | X3: =(4*I95+3*I66+2*I3+I19+I35)/11 -> 132.36364 | ... AB3: =(4*M95+3*M66+2*M3+M19+M35)/11 -> 138.45455
A4: 2 | B4: 1124 | C4: 326 | D4: 1077 | E4: 200 | F4: 0.3403 | G4: 0.4611 | H4: 1759 | I4: 115 | J4: 3.689 | K4: 1.186 | L4: 3.513 | M4: 133 | P4: 2 | Q4: =(4*B96+3*B67+2*B4+B20+B36)/11 -> 1066 | R4: =(4*C96+3*C67+2*C4+C20+C36)/11 -> 321.81818 | S4: =(4*D96+3*D67+2*D4+D20+D36)/11 -> 1028.5455 | T4: =(4*E96+3*E67+2*E4+E20+E36)/11 -> 205.45455 | U4: =(4*F96+3*F67+2*F4+F20+F36)/11 -> 0.33784545 | V4: =(4*G96+3*G67+2*G4+G20+G36)/11 -> 0.45003636 | W4: =(4*H96+3*H67+2*H4+H20+H36)/11 -> 1728.7273 | X4: =(4*I96+3*I67+2*I4+I20+I36)/11 -> 119.81818 | ... AB4: =(4*M96+3*M67+2*M4+M20+M36)/11 -> 122.27273
A5: 3 | B5: 1076 | C5: 323 | D5: 1063 | E5: 192 | F5: 0.3364 | G5: 0.4459 | H5: 1650 | I5: 112 | J5: 3.752 | K5: 1.205 | L5: 3.355 | M5: 112 | P5: 3 | Q5: =(4*B97+3*B68+2*B5+B21+B37)/11 -> 1049.3636 | R5: =(4*C97+3*C68+2*C5+C21+C37)/11 -> 300 | S5: =(4*D97+3*D68+2*D5+D21+D37)/11 -> 1013.0909 | T5: =(4*E97+3*E68+2*E5+E21+E37)/11 -> 194.81818 | U5: =(4*F97+3*F68+2*F5+F21+F37)/11 -> 0.33337273 | V5: =(4*G97+3*G68+2*G5+G21+G37)/11 -> 0.44380909 | W5: =(4*H97+3*H68+2*H5+H21+H37)/11 -> 1646.5455 | X5: =(4*I97+3*I68+2*I5+I21+I37)/11 -> 111.18182 | ... AB5: =(4*M97+3*M68+2*M5+M21+M37)/11 -> 116.18182
A6: 4 | B6: 1069 | C6: 308 | D6: 1049 | E6: 192 | F6: 0.3357 | G6: 0.4441 | H6: 1583 | I6: 111 | J6: 3.798 | K6: 1.232 | L6: 3.294 | M6: 108 | P6: 4 | Q6: =(4*B98+3*B69+2*B6+B22+B38)/11 -> 1037.6364 | R6: =(4*C98+3*C69+2*C6+C22+C38)/11 -> 295.72727 | S6: =(4*D98+3*D69+2*D6+D22+D38)/11 -> 998.18182 | T6: =(4*E98+3*E69+2*E6+E22+E38)/11 -> 179.72727 | U6: =(4*F98+3*F69+2*F6+F22+F38)/11 -> 0.33160909 | V6: =(4*G98+3*G69+2*G6+G22+G38)/11 -> 0.44090909 | W6: =(4*H98+3*H69+2*H6+H22+H38)/11 -> 1585.9091 | X6: =(4*I98+3*I69+2*I6+I22+I38)/11 -> 108.18182 | ... AB6: =(4*M98+3*M69+2*M6+M22+M38)/11 -> 110.63636
A7: 5 | B7: 1063 | C7: 304 | D7: 1048 | E7: 187 | F7: 0.3354 | G7: 0.4421 | H7: 1524 | I7: 104 | J7: 3.878 | K7: 1.233 | L7: 3.244 | M7: 95 | P7: 5 | Q7: =(4*B99+3*B70+2*B7+B23+B39)/11 -> 1022.3636 | R7: =(4*C99+3*C70+2*C7+C23+C39)/11 -> 291.36364 | S7: =(4*D99+3*D70+2*D7+D23+D39)/11 -> 988 | T7: =(4*E99+3*E70+2*E7+E23+E39)/11 -> 169.72727 | U7: =(4*F99+3*F70+2*F7+F23+F39)/11 -> 0.33005455 | V7: =(4*G99+3*G70+2*G7+G23+G39)/11 -> 0.43686364 | W7: =(4*H99+3*H70+2*H7+H23+H39)/11 -> 1509.1818 | X7: =(4*I99+3*I70+2*I7+I23+I39)/11 -> 102.36364 | ... AB7: =(4*M99+3*M70+2*M7+M23+M39)/11 -> 105.54545
A8: 6 | B8: 1059 | C8: 301 | D8: 1024 | E8: 185 | F8: 0.3319 | G8: 0.4415 | H8: 1446 | I8: 102 | J8: 3.95 | K8: 1.239 | L8: 3.209 | M8: 93 | P8: 6 | Q8: =(4*B100+3*B71+2*B8+B24+B40)/11 -> 1005.6364 | R8: =(4*C100+3*C71+2*C8+C24+C40)/11 -> 283.63636 | S8: =(4*D100+3*D71+2*D8+D24+D40)/11 -> 964.54545 | T8: =(4*E100+3*E71+2*E8+E24+E40)/11 -> 158.81818 | U8: =(4*F100+3*F71+2*F8+F24+F40)/11 -> 0.32835455 | V8: =(4*G100+3*G71+2*G8+G24+G40)/11 -> 0.43258182 | W8: =(4*H100+3*H71+2*H8+H24+H40)/11 -> 1469.3636 | X8: =(4*I100+3*I71+2*I8+I24+I40)/11 -> 100.63636 | ... AB8: =(4*M100+3*M71+2*M8+M24+M40)/11 -> 101.54545
A9: 7 | B9: 1032 | C9: 300 | D9: 1013 | E9: 164 | F9: 0.3307 | G9: 0.4391 | H9: 1405 | I9: 95 | J9: 4 | K9: 1.253 | L9: 3.168 | M9: 92 | P9: 7 | Q9: =(4*B101+3*B72+2*B9+B25+B41)/11 -> 997 | R9: =(4*C101+3*C72+2*C9+C25+C41)/11 -> 274.54545 | S9: =(4*D101+3*D72+2*D9+D25+D41)/11 -> 955.63636 | T9: =(4*E101+3*E72+2*E9+E25+E41)/11 -> 148.90909 | U9: =(4*F101+3*F72+2*F9+F25+F41)/11 -> 0.32626364 | V9: =(4*G101+3*G72+2*G9+G25+G41)/11 -> 0.43073636 | W9: =(4*H101+3*H72+2*H9+H25+H41)/11 -> 1436.9091 | X9: =(4*I101+3*I72+2*I9+I25+I41)/11 -> 96.363636 | ... AB9: =(4*M101+3*M72+2*M9+M25+M41)/11 -> 98
A10: 8 | B10: 1032 | C10: 294 | D10: 1004 | E10: 156 | F10: 0.3306 | G10: 0.4389 | H10: 1404 | I10: 94 | J10: 4.165 | K10: 1.264 | L10: 3.029 | M10: 92 | P10: 8 | Q10: =(4*B102+3*B73+2*B10+B26+B42)/11 -> 976.63636 | R10: =(4*C102+3*C73+2*C10+C26+C42)/11 -> 265.90909 | S10: =(4*D102+3*D73+2*D10+D26+D42)/11 -> 939.36364 | T10: =(4*E102+3*E73+2*E10+E26+E42)/11 -> 140.54545 | U10: =(4*F102+3*F73+2*F10+F26+F42)/11 -> 0.32465455 | V10: =(4*G102+3*G73+2*G10+G26+G42)/11 -> 0.4295 | W10: =(4*H102+3*H73+2*H10+H26+H42)/11 -> 1386.1818 | X10: =(4*I102+3*I73+2*I10+I26+I42)/11 -> 91 | ... AB10: =(4*M102+3*M73+2*M10+M26+M42)/11 -> 85.272727
A11: 9 | B11: 1028 | C11: 276 | D11: 994 | E11: 145 | F11: 0.3285 | G11: 0.4354 | H11: 1345 | I11: 90 | J11: 4.239 | K11: 1.272 | L11: 2.968 | M11: 84 | P11: 9 | Q11: =(4*B103+3*B74+2*B11+B27+B43)/11 -> 953.90909 | R11: =(4*C103+3*C74+2*C11+C27+C43)/11 -> 260.63636 | S11: =(4*D103+3*D74+2*D11+D27+D43)/11 -> 918.63636 | T11: =(4*E103+3*E74+2*E11+E27+E43)/11 -> 131 | U11: =(4*F103+3*F74+2*F11+F27+F43)/11 -> 0.32242727 | V11: =(4*G103+3*G74+2*G11+G27+G43)/11 -> 0.42624545 | W11: =(4*H103+3*H74+2*H11+H27+H43)/11 -> 1263.9091 | X11: =(4*I103+3*I74+2*I11+I27+I43)/11 -> 88.272727 | ... AB11: =(4*M103+3*M74+2*M11+M27+M43)/11 -> 77.636364
A12: 10 | B12: 1022 | C12: 276 | D12: 984 | E12: 126 | F12: 0.3269 | G12: 0.4322 | H12: 1344 | I12: 84 | J12: 4.275 | K12: 1.284 | L12: 2.903 | M12: 82 | P12: 10 | Q12: =(4*B104+3*B75+2*B12+B28+B44)/11 -> 943.18182 | R12: =(4*C104+3*C75+2*C12+C28+C44)/11 -> 257.18182 | S12: =(4*D104+3*D75+2*D12+D28+D44)/11 -> 906.45455 | T12: =(4*E104+3*E75+2*E12+E28+E44)/11 -> 114.54545 | U12: =(4*F104+3*F75+2*F12+F28+F44)/11 -> 0.32144545 | V12: =(4*G104+3*G75+2*G12+G28+G44)/11 -> 0.42245455 | W12: =(4*H104+3*H75+2*H12+H28+H44)/11 -> 1227.4545 | X12: =(4*I104+3*I75+2*I12+I28+I44)/11 -> 81.636364 | ... AB12: =(4*M104+3*M75+2*M12+M28+M44)/11 -> 73.454545
A13: 11 | B13: 993 | C13: 275 | D13: 921 | E13: 121 | F13: 0.324 | G13: 0.429 | H13: 1267 | I13: 72 | J13: 4.353 | K13: 1.288 | L13: 2.771 | M13: 58 | P13: 11 | Q13: =(4*B105+3*B76+2*B13+B29+B45)/11 -> 913.81818 | R13: =(4*C105+3*C76+2*C13+C29+C45)/11 -> 253.27273 | S13: =(4*D105+3*D76+2*D13+D29+D45)/11 -> 870.27273 | T13: =(4*E105+3*E76+2*E13+E29+E45)/11 -> 101.72727 | U13: =(4*F105+3*F76+2*F13+F29+F45)/11 -> 0.31948182 | V13: =(4*G105+3*G76+2*G13+G29+G45)/11 -> 0.41653636 | W13: =(4*H105+3*H76+2*H13+H29+H45)/11 -> 1179.6364 | X13: =(4*I105+3*I76+2*I13+I29+I45)/11 -> 67.272727 | ... AB13: =(4*M105+3*M76+2*M13+M29+M45)/11 -> 64.090909
A14: 12 | B14: 936 | C14: 250 | D14: 885 | E14: 98 | F14: 0.3227 | G14: 0.4236 | H14: 1104 | I14: 53 | J14: 4.518 | K14: 1.307 | L14: 2.686 | M14: 39 | P14: 12 | Q14: =(4*B106+3*B77+2*B14+B30+B46)/11 -> 884.81818 | R14: =(4*C106+3*C77+2*C14+C30+C46)/11 -> 212.18182 | S14: =(4*D106+3*D77+2*D14+D30+D46)/11 -> 818.36364 | T14: =(4*E106+3*E77+2*E14+E30+E46)/11 -> 75.727273 | U14: =(4*F106+3*F77+2*F14+F30+F46)/11 -> 0.31462727 | V14: =(4*G106+3*G77+2*G14+G30+G46)/11 -> 0.4121 | W14: =(4*H106+3*H77+2*H14+H30+H46)/11 -> 978.63636 | X14: =(4*I106+3*I77+2*I14+I30+I46)/11 -> 49.636364 | ... AB14: =(4*M106+3*M77+2*M14+M30+M46)/11 -> 52
B15: =-1*SLOPE(B4:B13,$A$4:$A$13) -> 11.406061 | C15: =-1*SLOPE(C4:C13,$A$4:$A$13) -> 5.9333333 | D15: =-1*SLOPE(D4:D13,$A$4:$A$13) -> 14.393939 | E15: =-1*SLOPE(E4:E13,$A$4:$A$13) -> 9.2242424 | F15: =-1*SLOPE(F4:F13,$A$4:$A$13) -> 0.0016048485 | G15: =-1*SLOPE(G4:G13,$A$4:$A$13) -> 0.0026684848 | H15: =-1*SLOPE(H4:H13,$A$4:$A$13) -> 49.460606 | I15: =-1*SLOPE(I4:I13,$A$4:$A$13) -> 4.3939394 | ... M15: =-1*SLOPE(M4:M13,$A$4:$A$13) -> 6.1515152
B16: =B15/$D$15 -> 0.79242105 | C16: =C15/$D$15 -> 0.41221053 | D16: =D15/$D$15 -> 1 | E16: =E15/$D$15 -> 0.64084211 | F16: =F15/$D$15 -> 0.00011149474 | G16: =G15/$D$15 -> 0.00018538947 | H16: =H15/$H$15 -> 1 | I16: =I15/$H$15 -> 0.088837152 | J16: =J15/$H$15 -> -0.0015626761 | K16: =K15/$H$15 -> -0.00021786546 | L16: =L15/$H$15 -> 0.0014897684 | M16: =M15/$H$15 -> 0.12437201
A17: 2022 | P17: MEAN | Q17: =AVERAGE(Q3:Q14) -> 993.77273 | R17: =AVERAGE(R3:R14) -> 279.2803 | S17: =AVERAGE(S3:S14) -> 956.88636 | T17: =AVERAGE(T3:T14) -> 153.09848 | U17: =AVERAGE(U3:U14) -> 0.32766136 | V17: =AVERAGE(V3:V14) -> 0.43352121 | W17: =AVERAGE(W3:W14) -> 1434.4091 | X17: =AVERAGE(X3:X14) -> 95.727273 | ... AB17: =AVERAGE(AB3:AB14) -> 95.424242
B18: R | C18: HR | D18: RBI | E18: SB | F18: OBP | G18: SLG | H18: K | I18: QS | J18: ERA | K18: WHIP | L18: K/BB | M18: SVHD | P18: MEAN/13 | Q18: =Q17/13 -> 76.444056 | R18: =R17/13 -> 21.4831 | S18: =S17/13 -> 73.606643 | T18: =T17/13 -> 11.776807 | U18: =U17 -> 0.32766136 | V18: =V17 -> 0.43352121 | W18: =W17/9 -> 159.37879 | X18: =X17/9 -> 10.636364 | Y18: =Y17 -> 3.8285076 | Z18: =Z17 -> 1.2065 | AA18: =AA17 -> 3.2234167 | AB18: =AB17/9 -> 10.602694
A19: 1 | B19: 1022 | C19: 300 | D19: 1038 | E19: 137 | F19: 0.3418 | G19: 0.4487 | H19: 1828 | I19: 131 | J19: 3.005 | K19: 1.074 | L19: 3.8 | M19: 143 | P19: STD | Q19: =_xlfn.STDEV.P(Q3:Q14) -> 58.086777 | R19: =_xlfn.STDEV.P(R3:R14) -> 31.629145 | S19: =_xlfn.STDEV.P(S3:S14) -> 69.264834 | T19: =_xlfn.STDEV.P(T3:T14) -> 41.083894 | U19: =_xlfn.STDEV.P(U3:U14) -> 0.0074824746 | V19: =_xlfn.STDEV.P(V3:V14) -> 0.013287797 | W19: =_xlfn.STDEV.P(W3:W14) -> 231.34567 | X19: =_xlfn.STDEV.P(X3:X14) -> 21.593987 | ... AB19: =_xlfn.STDEV.P(AB3:AB14) -> 24.411146
A20: 2 | B20: 1020 | C20: 294 | D20: 1006 | E20: 134 | F20: 0.337 | G20: 0.4363 | H20: 1794 | I20: 128 | J20: 3.24 | K20: 1.131 | L20: 3.799 | M20: 119 | P20: MEDIAN | Q20: =MEDIAN(Q3:Q14) -> 1001.3182 | R20: =MEDIAN(R3:R14) -> 279.09091 | S20: =MEDIAN(S3:S14) -> 960.09091 | T20: =MEDIAN(T3:T14) -> 153.86364 | U20: =MEDIAN(U3:U14) -> 0.32730909 | V20: =MEDIAN(V3:V14) -> 0.43165909 | W20: =MEDIAN(W3:W14) -> 1453.1364 | X20: =MEDIAN(X3:X14) -> 98.5 | ... AB20: =MEDIAN(AB3:AB14) -> 99.772727
A21: 3 | B21: 1004 | C21: 280 | D21: 998 | E21: 131 | F21: 0.3347 | G21: 0.4342 | H21: 1657 | I21: 120 | J21: 3.267 | K21: 1.131 | L21: 3.785 | M21: 118 | P21: VARIANCE | Q21: =_xlfn.VAR.P(Q3:Q14) -> 3374.0737 | R21: =_xlfn.VAR.P(R3:R14) -> 1000.4028 | S21: =_xlfn.VAR.P(S3:S14) -> 4797.6173 | T21: =_xlfn.VAR.P(T3:T14) -> 1687.8863 | U21: =_xlfn.VAR.P(U3:U14) -> 5.5987426e-05 | V21: =_xlfn.VAR.P(V3:V14) -> 0.00017656556 | W21: =_xlfn.VAR.P(W3:W14) -> 53520.817 | X21: =_xlfn.VAR.P(X3:X14) -> 466.30028 | ... AB21: =_xlfn.VAR.P(AB3:AB14) -> 595.90404
A22: 4 | B22: 990 | C22: 279 | D22: 990 | E22: 130 | F22: 0.3344 | G22: 0.4311 | H22: 1539 | I22: 114 | J22: 3.362 | K22: 1.15 | L22: 3.483 | M22: 108
A23: 5 | B23: 970 | C23: 277 | D23: 946 | E23: 121 | F23: 0.3322 | G23: 0.4303 | H23: 1511 | I23: 113 | J23: 3.368 | K23: 1.157 | L23: 3.324 | M23: 106 | W23: K | X23: QS | AB23: SVHD
A24: 6 | B24: 959 | C24: 272 | D24: 941 | E24: 120 | F24: 0.3317 | G24: 0.4267 | H24: 1503 | I24: 111 | J24: 3.405 | K24: 1.158 | L24: 3.271 | M24: 96 | S24: 2023 RPB | T24: 8.9282051 | V24: ADJ | W24: =(12*SLOPE(W4:W13,$P$4:$P$13)+INTERCEPT(W4:W13,$P$4:$P$13))/12 -> 92.818182 | X24: =(12*SLOPE(X4:X13,$P$4:$P$13)+INTERCEPT(X4:X13,$P$4:$P$13))/9 -> 7.7131313 | AB24: =(12*SLOPE(AB4:AB13,$P$4:$P$13)+INTERCEPT(AB4:AB13,$P$4:$P$13))/3 -> 20.131313
A25: 7 | B25: 946 | C25: 262 | D25: 915 | E25: 117 | F25: 0.3207 | G25: 0.4234 | H25: 1441 | I25: 102 | J25: 3.744 | K25: 1.199 | L25: 3.268 | M25: 90 | S25: 2023 ADM | T25: 9.2242424
A26: 8 | B26: 946 | C26: 251 | D26: 907 | E26: 115 | F26: 0.3206 | G26: 0.4204 | H26: 1230 | I26: 99 | J26: 3.962 | K26: 1.213 | L26: 3.224 | M26: 76 | P26: REGRESS BARR | Q26: =(12*SLOPE(Q4:Q13,$P$4:$P$13)+INTERCEPT(Q4:Q13,$P$4:$P$13))/13 -> 69.793007 | R26: =(12*SLOPE(R4:R13,$P$4:$P$13)+INTERCEPT(R4:R13,$P$4:$P$13))/13 -> 18.550583 | S26: =(12*SLOPE(S4:S13,$P$4:$P$13)+INTERCEPT(S4:S13,$P$4:$P$13))/13 -> 66.73007 | T26: =(12*SLOPE(T4:T13,$P$4:$P$13)+INTERCEPT(T4:T13,$P$4:$P$13))/13 -> 7.1776224 | U26: =(12*SLOPE(U4:U13,$P$4:$P$13)+INTERCEPT(U4:U13,$P$4:$P$13)) -> 0.31711879 | V26: =(12*SLOPE(V4:V13,$P$4:$P$13)+INTERCEPT(V4:V13,$P$4:$P$13)) -> 0.41469273 | W26: =(12*SLOPE(W4:W13,$P$4:$P$13)+INTERCEPT(W4:W13,$P$4:$P$13))/12 -> 92.818182 | X26: =(12*SLOPE(X4:X13,$P$4:$P$13)+INTERCEPT(X4:X13,$P$4:$P$13))/8 -> 8.6772727 | Y26: =(12*SLOPE(Y4:Y13,$P$4:$P$13)+INTERCEPT(Y4:Y13,$P$4:$P$13)) -> 4.2237152 | Z26: =(12*SLOPE(Z4:Z13,$P$4:$P$13)+INTERCEPT(Z4:Z13,$P$4:$P$13)) -> 1.2728788 | AA26: =(12*SLOPE(AA4:AA13,$P$4:$P$13)+INTERCEPT(AA4:AA13,$P$4:$P$13)) -> 2.7432848 | AB26: =(12*SLOPE(AB4:AB13,$P$4:$P$13)+INTERCEPT(AB4:AB13,$P$4:$P$13))/4 -> 15.098485
A27: 9 | B27: 945 | C27: 247 | D27: 878 | E27: 103 | F27: 0.3168 | G27: 0.4169 | H27: 1220 | I27: 96 | J27: 3.987 | K27: 1.225 | L27: 3.195 | M27: 60 | P27: SLOPE ADM | Q27: =-1*SLOPE(Q4:Q13,$P$4:$P$13) -> 16.226446 | R27: =-1*SLOPE(R4:R13,$P$4:$P$13) -> 7.1366391 | S27: =-1*SLOPE(S4:S13,$P$4:$P$13) -> 16.505785 | T27: =-1*SLOPE(T4:T13,$P$4:$P$13) -> 11.130579 | U27: =-1*SLOPE(U4:U13,$P$4:$P$13) -> 0.0018967493 | V27: =-1*SLOPE(V4:V13,$P$4:$P$13) -> 0.0033226446 | W27: =-1*SLOPE(W4:W13,$P$4:$P$13) -> 59.920661 | X27: =-1*SLOPE(X4:X13,$P$4:$P$13) -> 4.9553719 | ... AB27: =-1*SLOPE(AB4:AB13,$P$4:$P$13) -> 6.3763085
A28: 10 | B28: 940 | C28: 234 | D28: 855 | E28: 76 | F28: 0.3167 | G28: 0.4162 | H28: 1198 | I28: 93 | J28: 4.073 | K28: 1.236 | L28: 3.164 | M28: 37 | P28: RELATIVE SGP | Q28: =$S$27/Q27 -> 1.017215 | R28: =$S$27/R27 -> 2.3128233 | S28: =$S$27/S27 -> 1 | T28: =$S$27/T27 -> 1.4829225 | U28: =$S$27/U27/1000 -> 8.7021437 | V28: =$S$27/V27/1000 -> 4.9676649 | W28: =W27/$W$27 -> 1 | X28: =X27/$W$27 -> 0.082698886 | Y28: =Y27/$W$27 -> -0.001209662 | Z28: =Z27/$W$27 -> -0.00019592482 | AA28: =AA27/$W$27 -> 0.0014330428 | AB28: =AB27/$W$27 -> 0.10641252
A29: 11 | B29: 915 | C29: 229 | D29: 844 | E29: 75 | F29: 0.3142 | G29: 0.4138 | H29: 1174 | I29: 75 | J29: 4.119 | K29: 1.24 | L29: 3.115 | M29: 34
A30: 12 | B30: 894 | C30: 212 | D30: 804 | E30: 62 | F30: 0.3103 | G30: 0.4061 | H30: 1106 | I30: 60 | J30: 4.244 | K30: 1.247 | L30: 2.793 | M30: 30 | P30: ADM3 Outliers Filtered | Q30: =(IF(Q3<Q45,Q3,Q4)-IF(Q14>Q44,Q14,Q13))/(COUNT(IF(Q3<Q45,Q3,Q4):IF(Q14>Q44,Q14,Q13))-1) -> 17.280992 | R30: =(IF(R3<R45,R3,R4)-IF(R14>R44,R14,R13))/(COUNT(IF(R3<R45,R3,R4):IF(R14>R44,R14,R13))-1) -> 7.6161616 | S30: =(IF(S3<S45,S3,S4)-IF(S14>S44,S14,S13))/(COUNT(IF(S3<S45,S3,S4):IF(S14>S44,S14,S13))-1) -> 21.127273 | T30: =(IF(T3<T45,T3,T4)-IF(T14>T44,T14,T13))/(COUNT(IF(T3<T45,T3,T4):IF(T14>T44,T14,T13))-1) -> 12.768595 | U30: =(IF(U3<U45,U3,U4)-IF(U14>U44,U14,U13))/(COUNT(IF(U3<U45,U3,U4):IF(U14>U44,U14,U13))-1) -> 0.0024702479 | V30: =(IF(V3<V45,V3,V4)-IF(V14>V44,V14,V13))/(COUNT(IF(V3<V45,V3,V4):IF(V14>V44,V14,V13))-1) -> 0.0037936364 | W30: =(IF(W3<W45,W3,W4)-IF(W14>W44,W14,W13))/(COUNT(IF(W3<W45,W3,W4):IF(W14>W44,W14,W13))-1) -> 74.710744 | X30: =(IF(X3<X45,X3,X4)-IF(X14>X44,X14,X13))/(COUNT(IF(X3<X45,X3,X4):IF(X14>X44,X14,X13))-1) -> 5.8383838 | ... AB30: =(IF(AB3<AB45,AB3,AB4)-IF(AB14>AB44,AB14,AB13))/(COUNT(IF(AB3<AB45,AB3,AB4):IF(AB14>AB44,AB14,AB13))-1) -> 7.8595041
B31: =-1*SLOPE(B20:B29,$A$20:$A$29) -> 10.321212 | C31: =-1*SLOPE(C20:C29,$A$20:$A$29) -> 7 | D31: =-1*SLOPE(D20:D29,$A$20:$A$29) -> 19.163636 | E31: =-1*SLOPE(E20:E29,$A$20:$A$29) -> 6.4969697 | F31: =-1*SLOPE(F20:F29,$A$20:$A$29) -> 0.0028181818 | G31: =-1*SLOPE(G20:G29,$A$20:$A$29) -> 0.0026212121 | H31: =-1*SLOPE(H20:H29,$A$20:$A$29) -> 68.442424 | I31: =-1*SLOPE(I20:I29,$A$20:$A$29) -> 4.8909091 | ... M31: =-1*SLOPE(M20:M29,$A$20:$A$29) -> 10.109091 | P31: ADM3 ACTUAL | Q31: =(Q3-Q14)/11 -> 17.280992 | R31: =(R3-R14)/11 -> 11.173554 | S31: =(S3-S14)/11 -> 23.92562 | T31: =(T3-T14)/11 -> 12.768595 | U31: =(U3-U14)/11 -> 0.0024702479 | V31: =(V3-V14)/11 -> 0.0043983471 | W31: =(W3-W14)/11 -> 74.710744 | X31: =(X3-X14)/11 -> 7.5206612 | ... AB31: =(AB3-AB14)/11 -> 7.8595041
B32: =B31/$D$31 -> 0.53858318 | C32: =C31/$D$31 -> 0.36527514 | D32: =D31/$D$31 -> 1 | E32: =E31/$D$31 -> 0.33902593 | F32: =F31/$D$31 -> 0.00014705882 | G32: =G31/$D$31 -> 0.00013678052 | H32: =H31/$H$31 -> 1 | I32: =I31/$H$31 -> 0.071460197 | J32: =J31/$H$31 -> -0.0016646595 | K32: =K31/$H$31 -> -0.00020366599 | L32: =L31/$H$31 -> 0.0010843886 | M32: =M31/$H$31 -> 0.14770212 | P32: MAX | Q32: =MAX(Q3:Q14) -> 1074.9091 | R32: =MAX(R3:R14) -> 335.09091 | S32: =MAX(S3:S14) -> 1081.5455 | T32: =MAX(T3:T14) -> 216.18182 | U32: =MAX(U3:U14) -> 0.3418 | V32: =MAX(V3:V14) -> 0.46048182 | W32: =MAX(W3:W14) -> 1800.4545 | X32: =MAX(X3:X14) -> 132.36364 | ... AB32: =MAX(AB3:AB14) -> 138.45455
A33: 2021 | P33: MIN | Q33: =MIN(Q3:Q14) -> 884.81818 | R33: =MIN(R3:R14) -> 212.18182 | S33: =MIN(S3:S14) -> 818.36364 | T33: =MIN(T3:T14) -> 75.727273 | U33: =MIN(U3:U14) -> 0.31462727 | V33: =MIN(V3:V14) -> 0.4121 | W33: =MIN(W3:W14) -> 978.63636 | X33: =MIN(X3:X14) -> 49.636364 | ... AB33: =MIN(AB3:AB14) -> 52
A34: RANK | B34: R | C34: HR | D34: RBI | E34: SB | F34: OBP | G34: SLG | H34: K | I34: QS | J34: ERA | K34: WHIP | L34: K/BB | M34: SV | P34: CV | Q34: =100*Q19/Q17 -> 5.8450766 | R34: =100*R19/R17 -> 11.325233 | S34: =100*S19/S17 -> 7.2385642 | T34: =100*T19/T17 -> 26.834945 | U34: =100*U19/U17 -> 2.2835999 | V34: =100*V19/V17 -> 3.0650858 | W34: =100*W19/W17 -> 16.128291 | X34: =100*X19/X17 -> 22.557821 | ... AB34: =100*AB19/AB17 -> 25.581703
A35: 1 | B35: 1102 | C35: 317 | D35: 1082 | E35: 165 | F35: 0.3479 | G35: 0.4715 | H35: 1665 | I35: 118 | J35: 3.427 | K35: 1.124 | L35: 3.997 | M35: 119 | P35: 2023 Ranks | Q35: 7 | R35: 5 | S35: 6 | T35: 8 | U35: 3 | V35: 4 | W35: 3 | X35: 2 | Y35: 2 | Z35: 2 | AA35: 2 | AB35: 3
A36: 2 | B36: 1068 | C36: 315 | D36: 1017 | E36: 132 | F36: 0.347 | G36: 0.4691 | H36: 1654 | I36: 117 | J36: 3.436 | K36: 1.133 | L36: 3.808 | M36: 95 | Q36: R | R36: HR | S36: RBI | T36: SB | U36: OBP | V36: SLG | W36: K | X36: QS | Y36: ERA | Z36: WHIP | AA36: K/BB | AB36: SVHD
A37: 3 | B37: 1068 | C37: 313 | D37: 1013 | E37: 130 | F37: 0.3399 | G37: 0.467 | H37: 1649 | I37: 116 | J37: 3.531 | K37: 1.134 | L37: 3.753 | M37: 92 | P37: 3 | Q37: =Q5 -> 1049.3636 | R37: =R5 -> 300 | S37: =S5 -> 1013.0909 | T37: =T5 -> 194.81818 | U37: =U5 -> 0.33337273 | V37: =V5 -> 0.44380909 | W37: =W5 -> 1646.5455 | X37: =X5 -> 111.18182 | ... AB37: =AB5 -> 116.18182
A38: 4 | B38: 1043 | C38: 313 | D38: 1009 | E38: 124 | F38: 0.3392 | G38: 0.4585 | H38: 1566 | I38: 110 | J38: 3.612 | K38: 1.145 | L38: 3.691 | M38: 89 | P38: 3rd in Historical Data | Q38: =Q37/13 -> 80.72028 | R38: =R37/13 -> 23.076923 | S38: =S37/13 -> 77.93007 | T38: =T37/13 -> 14.986014 | U38: =U37 -> 0.33337273 | V38: =V37 -> 0.44380909 | W38: =W37/9 -> 182.94949 | X38: =X37/9 -> 12.353535 | Y38: =Y37 -> 3.5865455 | Z38: =Z37 -> 1.1639091 | AA38: =AA37 -> 3.4907273 | AB38: =AB37/9 -> 12.909091
A39: 5 | B39: 1041 | C39: 305 | D39: 985 | E39: 117 | F39: 0.3392 | G39: 0.4581 | H39: 1547 | I39: 104 | J39: 3.619 | K39: 1.164 | L39: 3.547 | M39: 77 | P39: 3RD FITTED LINE TEAM | Q39: =3*SLOPE(Q4:Q13,$P$4:$P$13)+INTERCEPT(Q4:Q13,$P$4:$P$13) -> 1053.3471 | R39: =3*SLOPE(R4:R13,$P$4:$P$13)+INTERCEPT(R4:R13,$P$4:$P$13) -> 305.38733 | S39: =3*SLOPE(S4:S13,$P$4:$P$13)+INTERCEPT(S4:S13,$P$4:$P$13) -> 1016.043 | T39: =3*SLOPE(T4:T13,$P$4:$P$13)+INTERCEPT(T4:T13,$P$4:$P$13) -> 193.4843 | U39: =3*SLOPE(U4:U13,$P$4:$P$13)+INTERCEPT(U4:U13,$P$4:$P$13) -> 0.33418953 | V39: =3*SLOPE(V4:V13,$P$4:$P$13)+INTERCEPT(V4:V13,$P$4:$P$13) -> 0.44459653 | W39: =3*SLOPE(W4:W13,$P$4:$P$13)+INTERCEPT(W4:W13,$P$4:$P$13) -> 1653.1041 | X39: =3*SLOPE(X4:X13,$P$4:$P$13)+INTERCEPT(X4:X13,$P$4:$P$13) -> 114.01653 | ... AB39: =3*SLOPE(AB4:AB13,$P$4:$P$13)+INTERCEPT(AB4:AB13,$P$4:$P$13) -> 117.78072
A40: 6 | B40: 1002 | C40: 293 | D40: 972 | E40: 115 | F40: 0.3389 | G40: 0.4505 | H40: 1486 | I40: 101 | J40: 3.682 | K40: 1.188 | L40: 3.364 | M40: 58 | P40: 3RD FL PLAYER | Q40: =Q39/13 -> 81.026701 | R40: =R39/13 -> 23.491333 | S40: =S39/13 -> 78.157152 | T40: =T39/13 -> 14.883408 | U40: =U39 -> 0.33418953 | V40: =V39 -> 0.44459653 | W40: =W39/9 -> 183.67824 | X40: =X39/9 -> 12.668503 | Y40: =Y39 -> 3.5713614 | Z40: =Z39 -> 1.1672193 | AA40: =AA39 -> 3.5161047 | AB40: =AB39/9 -> 13.086746
...

Sheet Parameters
A1: R | B1: ='Historical Data'!$Q26 -> 69.793007 | C1: ='Historical Data'!$Q27 -> 16.226446
A2: HR | B2: ='Historical Data'!$R26 -> 18.550583 | C2: ='Historical Data'!$R27 -> 7.1366391
A3: RBI | B3: ='Historical Data'!$S26 -> 66.73007 | C3: ='Historical Data'!$S27 -> 16.505785
A4: SB | B4: ='Historical Data'!$T26 -> 7.1776224 | C4: ='Historical Data'!$T27 -> 11.130579
A5: OBP | B5: ='Historical Data'!$U26 -> 0.31711879 | C5: ='Historical Data'!$U27 -> 0.0018967493
A6: SLG | B6: ='Historical Data'!$V26 -> 0.41469273 | C6: ='Historical Data'!$V27 -> 0.0033226446
A7: SO | B7: ='Historical Data'!$W26 -> 92.818182 | C7: ='Historical Data'!$W27 -> 59.920661
A8: QS | B8: ='Historical Data'!$X26 -> 8.6772727 | C8: ='Historical Data'!$X27 -> 4.9553719
A9: ERA | B9: ='Historical Data'!$Y26 -> 4.2237152 | C9: ='Historical Data'!$Y27 -> -0.072483747
A10: WHIP | B10: ='Historical Data'!$Z26 -> 1.2728788 | C10: ='Historical Data'!$Z27 -> -0.011739945
A11: K/BB | B11: ='Historical Data'!$AA26 -> 2.7432848 | C11: ='Historical Data'!$AA27 -> 0.085868871
A12: SV_HLD | B12: ='Historical Data'!$AB26 -> 15.098485 | C12: ='Historical Data'!$AB27 -> 6.3763085
